 * Running on http://0.0.0.0:5177/ (Press CTRL+C to quit)
127.0.0.1 - - [10/Dec/2018 11:31:09] "GET / HTTP/1.1" 200 -
127.0.0.1 - - [10/Dec/2018 11:31:10] "GET /favicon.ico HTTP/1.1" 404 -
Traceback (most recent call last):
  File "/Users/apple/.virtualenvs/flask-pymongo/bin/flask", line 11, in <module>
    sys.exit(main())
  File "/Users/apple/.virtualenvs/flask-pymongo/lib/python3.7/site-packages/flask/cli.py", line 894, in main
    cli.main(args=args, prog_name=name)
  File "/Users/apple/.virtualenvs/flask-pymongo/lib/python3.7/site-packages/flask/cli.py", line 557, in main
    return super(FlaskGroup, self).main(*args, **kwargs)
  File "/Users/apple/.virtualenvs/flask-pymongo/lib/python3.7/site-packages/click/core.py", line 717, in main
    rv = self.invoke(ctx)
  File "/Users/apple/.virtualenvs/flask-pymongo/lib/python3.7/site-packages/click/core.py", line 1137, in invoke
    return _process_result(sub_ctx.command.invoke(sub_ctx))
  File "/Users/apple/.virtualenvs/flask-pymongo/lib/python3.7/site-packages/click/core.py", line 956, in invoke
    return ctx.invoke(self.callback, **ctx.params)
  File "/Users/apple/.virtualenvs/flask-pymongo/lib/python3.7/site-packages/click/core.py", line 555, in invoke
    return callback(*args, **kwargs)
  File "/Users/apple/.virtualenvs/flask-pymongo/lib/python3.7/site-packages/click/decorators.py", line 64, in new_func
    return ctx.invoke(f, obj, *args, **kwargs)
  File "/Users/apple/.virtualenvs/flask-pymongo/lib/python3.7/site-packages/click/core.py", line 555, in invoke
    return callback(*args, **kwargs)
  File "/Users/apple/.virtualenvs/flask-pymongo/lib/python3.7/site-packages/flask/cli.py", line 771, in run_command
    threaded=with_threads, ssl_context=cert)
  File "/Users/apple/.virtualenvs/flask-pymongo/lib/python3.7/site-packages/werkzeug/serving.py", line 814, in run_simple
    inner()
  File "/Users/apple/.virtualenvs/flask-pymongo/lib/python3.7/site-packages/werkzeug/serving.py", line 774, in inner
    fd=fd)
  File "/Users/apple/.virtualenvs/flask-pymongo/lib/python3.7/site-packages/werkzeug/serving.py", line 660, in make_server
    passthrough_errors, ssl_context, fd=fd)
  File "/Users/apple/.virtualenvs/flask-pymongo/lib/python3.7/site-packages/werkzeug/serving.py", line 577, in __init__
    self.address_family), handler)
  File "/usr/local/Cellar/python/3.7.0/Frameworks/Python.framework/Versions/3.7/lib/python3.7/socketserver.py", line 449, in __init__
    self.server_bind()
  File "/usr/local/Cellar/python/3.7.0/Frameworks/Python.framework/Versions/3.7/lib/python3.7/http/server.py", line 137, in server_bind
    socketserver.TCPServer.server_bind(self)
  File "/usr/local/Cellar/python/3.7.0/Frameworks/Python.framework/Versions/3.7/lib/python3.7/socketserver.py", line 463, in server_bind
    self.socket.bind(self.server_address)
OSError: [Errno 48] Address already in use
Traceback (most recent call last):
  File "/Users/apple/.virtualenvs/flask-pymongo/bin/flask", line 11, in <module>
    sys.exit(main())
  File "/Users/apple/.virtualenvs/flask-pymongo/lib/python3.7/site-packages/flask/cli.py", line 894, in main
    cli.main(args=args, prog_name=name)
  File "/Users/apple/.virtualenvs/flask-pymongo/lib/python3.7/site-packages/flask/cli.py", line 557, in main
    return super(FlaskGroup, self).main(*args, **kwargs)
  File "/Users/apple/.virtualenvs/flask-pymongo/lib/python3.7/site-packages/click/core.py", line 717, in main
    rv = self.invoke(ctx)
  File "/Users/apple/.virtualenvs/flask-pymongo/lib/python3.7/site-packages/click/core.py", line 1137, in invoke
    return _process_result(sub_ctx.command.invoke(sub_ctx))
  File "/Users/apple/.virtualenvs/flask-pymongo/lib/python3.7/site-packages/click/core.py", line 956, in invoke
    return ctx.invoke(self.callback, **ctx.params)
  File "/Users/apple/.virtualenvs/flask-pymongo/lib/python3.7/site-packages/click/core.py", line 555, in invoke
    return callback(*args, **kwargs)
  File "/Users/apple/.virtualenvs/flask-pymongo/lib/python3.7/site-packages/click/decorators.py", line 64, in new_func
    return ctx.invoke(f, obj, *args, **kwargs)
  File "/Users/apple/.virtualenvs/flask-pymongo/lib/python3.7/site-packages/click/core.py", line 555, in invoke
    return callback(*args, **kwargs)
  File "/Users/apple/.virtualenvs/flask-pymongo/lib/python3.7/site-packages/flask/cli.py", line 771, in run_command
    threaded=with_threads, ssl_context=cert)
  File "/Users/apple/.virtualenvs/flask-pymongo/lib/python3.7/site-packages/werkzeug/serving.py", line 814, in run_simple
    inner()
  File "/Users/apple/.virtualenvs/flask-pymongo/lib/python3.7/site-packages/werkzeug/serving.py", line 774, in inner
    fd=fd)
  File "/Users/apple/.virtualenvs/flask-pymongo/lib/python3.7/site-packages/werkzeug/serving.py", line 660, in make_server
    passthrough_errors, ssl_context, fd=fd)
  File "/Users/apple/.virtualenvs/flask-pymongo/lib/python3.7/site-packages/werkzeug/serving.py", line 577, in __init__
    self.address_family), handler)
  File "/usr/local/Cellar/python/3.7.0/Frameworks/Python.framework/Versions/3.7/lib/python3.7/socketserver.py", line 449, in __init__
    self.server_bind()
  File "/usr/local/Cellar/python/3.7.0/Frameworks/Python.framework/Versions/3.7/lib/python3.7/http/server.py", line 137, in server_bind
    socketserver.TCPServer.server_bind(self)
  File "/usr/local/Cellar/python/3.7.0/Frameworks/Python.framework/Versions/3.7/lib/python3.7/socketserver.py", line 463, in server_bind
    self.socket.bind(self.server_address)
OSError: [Errno 48] Address already in use
Traceback (most recent call last):
  File "/Users/apple/.virtualenvs/flask-pymongo/bin/flask", line 11, in <module>
    sys.exit(main())
  File "/Users/apple/.virtualenvs/flask-pymongo/lib/python3.7/site-packages/flask/cli.py", line 894, in main
    cli.main(args=args, prog_name=name)
  File "/Users/apple/.virtualenvs/flask-pymongo/lib/python3.7/site-packages/flask/cli.py", line 557, in main
    return super(FlaskGroup, self).main(*args, **kwargs)
  File "/Users/apple/.virtualenvs/flask-pymongo/lib/python3.7/site-packages/click/core.py", line 717, in main
    rv = self.invoke(ctx)
  File "/Users/apple/.virtualenvs/flask-pymongo/lib/python3.7/site-packages/click/core.py", line 1137, in invoke
    return _process_result(sub_ctx.command.invoke(sub_ctx))
  File "/Users/apple/.virtualenvs/flask-pymongo/lib/python3.7/site-packages/click/core.py", line 956, in invoke
    return ctx.invoke(self.callback, **ctx.params)
  File "/Users/apple/.virtualenvs/flask-pymongo/lib/python3.7/site-packages/click/core.py", line 555, in invoke
    return callback(*args, **kwargs)
  File "/Users/apple/.virtualenvs/flask-pymongo/lib/python3.7/site-packages/click/decorators.py", line 64, in new_func
    return ctx.invoke(f, obj, *args, **kwargs)
  File "/Users/apple/.virtualenvs/flask-pymongo/lib/python3.7/site-packages/click/core.py", line 555, in invoke
    return callback(*args, **kwargs)
  File "/Users/apple/.virtualenvs/flask-pymongo/lib/python3.7/site-packages/flask/cli.py", line 771, in run_command
    threaded=with_threads, ssl_context=cert)
  File "/Users/apple/.virtualenvs/flask-pymongo/lib/python3.7/site-packages/werkzeug/serving.py", line 814, in run_simple
    inner()
  File "/Users/apple/.virtualenvs/flask-pymongo/lib/python3.7/site-packages/werkzeug/serving.py", line 774, in inner
    fd=fd)
  File "/Users/apple/.virtualenvs/flask-pymongo/lib/python3.7/site-packages/werkzeug/serving.py", line 660, in make_server
    passthrough_errors, ssl_context, fd=fd)
  File "/Users/apple/.virtualenvs/flask-pymongo/lib/python3.7/site-packages/werkzeug/serving.py", line 577, in __init__
    self.address_family), handler)
  File "/usr/local/Cellar/python/3.7.0/Frameworks/Python.framework/Versions/3.7/lib/python3.7/socketserver.py", line 449, in __init__
    self.server_bind()
  File "/usr/local/Cellar/python/3.7.0/Frameworks/Python.framework/Versions/3.7/lib/python3.7/http/server.py", line 137, in server_bind
    socketserver.TCPServer.server_bind(self)
  File "/usr/local/Cellar/python/3.7.0/Frameworks/Python.framework/Versions/3.7/lib/python3.7/socketserver.py", line 463, in server_bind
    self.socket.bind(self.server_address)
OSError: [Errno 48] Address already in use
Traceback (most recent call last):
  File "/Users/apple/.virtualenvs/flask-pymongo/bin/flask", line 11, in <module>
    sys.exit(main())
  File "/Users/apple/.virtualenvs/flask-pymongo/lib/python3.7/site-packages/flask/cli.py", line 894, in main
    cli.main(args=args, prog_name=name)
  File "/Users/apple/.virtualenvs/flask-pymongo/lib/python3.7/site-packages/flask/cli.py", line 557, in main
    return super(FlaskGroup, self).main(*args, **kwargs)
  File "/Users/apple/.virtualenvs/flask-pymongo/lib/python3.7/site-packages/click/core.py", line 717, in main
    rv = self.invoke(ctx)
  File "/Users/apple/.virtualenvs/flask-pymongo/lib/python3.7/site-packages/click/core.py", line 1137, in invoke
    return _process_result(sub_ctx.command.invoke(sub_ctx))
  File "/Users/apple/.virtualenvs/flask-pymongo/lib/python3.7/site-packages/click/core.py", line 956, in invoke
    return ctx.invoke(self.callback, **ctx.params)
  File "/Users/apple/.virtualenvs/flask-pymongo/lib/python3.7/site-packages/click/core.py", line 555, in invoke
    return callback(*args, **kwargs)
  File "/Users/apple/.virtualenvs/flask-pymongo/lib/python3.7/site-packages/click/decorators.py", line 64, in new_func
    return ctx.invoke(f, obj, *args, **kwargs)
  File "/Users/apple/.virtualenvs/flask-pymongo/lib/python3.7/site-packages/click/core.py", line 555, in invoke
    return callback(*args, **kwargs)
  File "/Users/apple/.virtualenvs/flask-pymongo/lib/python3.7/site-packages/flask/cli.py", line 771, in run_command
    threaded=with_threads, ssl_context=cert)
  File "/Users/apple/.virtualenvs/flask-pymongo/lib/python3.7/site-packages/werkzeug/serving.py", line 814, in run_simple
    inner()
  File "/Users/apple/.virtualenvs/flask-pymongo/lib/python3.7/site-packages/werkzeug/serving.py", line 774, in inner
    fd=fd)
  File "/Users/apple/.virtualenvs/flask-pymongo/lib/python3.7/site-packages/werkzeug/serving.py", line 660, in make_server
    passthrough_errors, ssl_context, fd=fd)
  File "/Users/apple/.virtualenvs/flask-pymongo/lib/python3.7/site-packages/werkzeug/serving.py", line 577, in __init__
    self.address_family), handler)
  File "/usr/local/Cellar/python/3.7.0/Frameworks/Python.framework/Versions/3.7/lib/python3.7/socketserver.py", line 449, in __init__
    self.server_bind()
  File "/usr/local/Cellar/python/3.7.0/Frameworks/Python.framework/Versions/3.7/lib/python3.7/http/server.py", line 137, in server_bind
    socketserver.TCPServer.server_bind(self)
  File "/usr/local/Cellar/python/3.7.0/Frameworks/Python.framework/Versions/3.7/lib/python3.7/socketserver.py", line 463, in server_bind
    self.socket.bind(self.server_address)
OSError: [Errno 48] Address already in use
